
TASK [Create an AKS instance] **************************************************
An exception occurred during task execution. To see the full traceback, use -vvv. The error was: AttributeError: 'ManagedClustersOperations' object has no attribute 'get_access_profiles'
fatal: [localhost]: FAILED! => {"changed": false, "module_stderr": "Traceback (most recent call last):\n  File \"/root/.ansible/tmp/ansible-tmp-1545618545.25-236010869695211/AnsiballZ_azure_rm_aks.py\", line 113, in <module>\n    _ansiballz_main()\n  File \"/root/.ansible/tmp/ansible-tmp-1545618545.25-236010869695211/AnsiballZ_azure_rm_aks.py\", line 105, in _ansiballz_main\n    invoke_module(zipped_mod, temp_path, ANSIBALLZ_PARAMS)\n  File \"/root/.ansible/tmp/ansible-tmp-1545618545.25-236010869695211/AnsiballZ_azure_rm_aks.py\", line 48, in invoke_module\n    imp.load_module('__main__', mod, module, MOD_DESC)\n  File \"/tmp/ansible_azure_rm_aks_payload_sYqZcU/__main__.py\", line 611, in <module>\n  File \"/tmp/ansible_azure_rm_aks_payload_sYqZcU/__main__.py\", line 607, in main\n  File \"/tmp/ansible_azure_rm_aks_payload_sYqZcU/__main__.py\", line 400, in __init__\n  File \"/tmp/ansible_azure_rm_aks_payload_sYqZcU/ansible_azure_rm_aks_payload.zip/ansible/module_utils/azure_rm_common.py\", line 310, in __init__\n  File \"/tmp/ansible_azure_rm_aks_payload_sYqZcU/__main__.py\", line 496, in exec_module\n  File \"/tmp/ansible_azure_rm_aks_payload_sYqZcU/__main__.py\", line 552, in create_update_aks\n  File \"/tmp/ansible_azure_rm_aks_payload_sYqZcU/__main__.py\", line 600, in get_aks_kubeconfig\nAttributeError: 'ManagedClustersOperations' object has no attribute 'get_access_profiles'\n", "module_stdout": "", "msg": "MODULE FAILURE\nSee stdout/stderr for the exact error", "rc": 1}
	to retry, use: --limit @/home/azureuser/main.retry

PLAY RECAP *********************************************************************
localhost                  : ok=6    changed=1    unreachable=0    failed=1    skipped=0 
