
TASK [Upgrade the AKS instance with addon] *************************************
An exception occurred during task execution. To see the full traceback, use -vvv. The error was: UnboundLocalError: local variable 'available_versions' referenced before assignment
fatal: [localhost]: FAILED! => {"changed": false, "module_stderr": "Traceback (most recent call last):\n  File \"/home/azureuser/.ansible/tmp/ansible-tmp-1553576968.41-182010439403740/AnsiballZ_azure_rm_aks.py\", line 114, in <module>\n    _ansiballz_main()\n  File \"/home/azureuser/.ansible/tmp/ansible-tmp-1553576968.41-182010439403740/AnsiballZ_azure_rm_aks.py\", line 106, in _ansiballz_main\n    invoke_module(zipped_mod, temp_path, ANSIBALLZ_PARAMS)\n  File \"/home/azureuser/.ansible/tmp/ansible-tmp-1553576968.41-182010439403740/AnsiballZ_azure_rm_aks.py\", line 49, in invoke_module\n    imp.load_module('__main__', mod, module, MOD_DESC)\n  File \"/tmp/ansible_azure_rm_aks_payload_2AoEa2/__main__.py\", line 829, in <module>\n  File \"/tmp/ansible_azure_rm_aks_payload_2AoEa2/__main__.py\", line 825, in main\n  File \"/tmp/ansible_azure_rm_aks_payload_2AoEa2/__main__.py\", line 517, in __init__\n  File \"/tmp/ansible_azure_rm_aks_payload_2AoEa2/ansible_azure_rm_aks_payload.zip/ansible/module_utils/azure_rm_common.py\", line 319, in __init__\n  File \"/tmp/ansible_azure_rm_aks_payload_2AoEa2/__main__.py\", line 585, in exec_module\nUnboundLocalError: local variable 'available_versions' referenced before assignment\n", "module_stdout": "", "msg": "MODULE FAILURE\nSee stdout/stderr for the exact error", "rc": 1}

PLAY RECAP *********************************************************************
localhost                  : ok=15   changed=3    unreachable=0    failed=1    skipped=0    rescued=0    ignored=0  
